Workbook

Sheet PVR
A1: Id | B1: Servicio | C1: Escandallo Total | D1: Beneficio | E1: IVA | F1: PVR
A2: =Tabla5[[#This Row],[Id]] -> 0 | B2: =VLOOKUP(Tabla57[[#This Row],[Id]],Tabla5[[Id]:[Escandallo Total]],2,FALSE) -> Prueba | C2: =VLOOKUP(Tabla57[[#This Row],[Id]],Tabla5[[Id]:[Escandallo Total]],4,FALSE) -> 85.724731 | D2: =Tabla57[[#This Row],[Escandallo Total]]*Datos!$B$2+Tabla57[[#This Row],[Escandallo Total]] -> 128.5871 | E2: =Tabla57[[#This Row],[Beneficio]]*Datos!$B$1+Tabla57[[#This Row],[Beneficio]] -> 155.59039
A3: 1 | B3: =VLOOKUP(Tabla57[[#This Row],[Id]],Tabla5[[Id]:[Escandallo Total]],2,FALSE) -> Mesodermolifting | C3: =VLOOKUP(Tabla57[[#This Row],[Id]],Tabla5[[Id]:[Escandallo Total]],4,FALSE) -> 34.712457 | D3: =Tabla57[[#This Row],[Escandallo Total]]*Datos!$B$2+Tabla57[[#This Row],[Escandallo Total]] -> 52.068686 | E3: =Tabla57[[#This Row],[Beneficio]]*Datos!$B$1+Tabla57[[#This Row],[Beneficio]] -> 63.00311 | F3: 100
A4: 2 | B4: =VLOOKUP(Tabla57[[#This Row],[Id]],Tabla5[[Id]:[Escandallo Total]],2,FALSE) -> 0 | C4: =VLOOKUP(Tabla57[[#This Row],[Id]],Tabla5[[Id]:[Escandallo Total]],4,FALSE) -> 0 | D4: =Tabla57[[#This Row],[Escandallo Total]]*Datos!$B$2+Tabla57[[#This Row],[Escandallo Total]] -> 0 | E4: =Tabla57[[#This Row],[Beneficio]]*Datos!$B$1+Tabla57[[#This Row],[Beneficio]] -> 0
A5: 3 | B5: =VLOOKUP(Tabla57[[#This Row],[Id]],Tabla5[[Id]:[Escandallo Total]],2,FALSE) -> 0 | C5: =VLOOKUP(Tabla57[[#This Row],[Id]],Tabla5[[Id]:[Escandallo Total]],4,FALSE) -> 0 | D5: =Tabla57[[#This Row],[Escandallo Total]]*Datos!$B$2+Tabla57[[#This Row],[Escandallo Total]] -> 0 | E5: =Tabla57[[#This Row],[Beneficio]]*Datos!$B$1+Tabla57[[#This Row],[Beneficio]] -> 0
A6: 4 | B6: =VLOOKUP(Tabla57[[#This Row],[Id]],Tabla5[[Id]:[Escandallo Total]],2,FALSE) -> 0 | C6: =VLOOKUP(Tabla57[[#This Row],[Id]],Tabla5[[Id]:[Escandallo Total]],4,FALSE) -> 0 | D6: =Tabla57[[#This Row],[Escandallo Total]]*Datos!$B$2+Tabla57[[#This Row],[Escandallo Total]] -> 0 | E6: =Tabla57[[#This Row],[Beneficio]]*Datos!$B$1+Tabla57[[#This Row],[Beneficio]] -> 0
A7: 5 | B7: =VLOOKUP(Tabla57[[#This Row],[Id]],Tabla5[[Id]:[Escandallo Total]],2,FALSE) -> 0 | C7: =VLOOKUP(Tabla57[[#This Row],[Id]],Tabla5[[Id]:[Escandallo Total]],4,FALSE) -> 0 | D7: =Tabla57[[#This Row],[Escandallo Total]]*Datos!$B$2+Tabla57[[#This Row],[Escandallo Total]] -> 0 | E7: =Tabla57[[#This Row],[Beneficio]]*Datos!$B$1+Tabla57[[#This Row],[Beneficio]] -> 0
A8: 6 | B8: =VLOOKUP(Tabla57[[#This Row],[Id]],Tabla5[[Id]:[Escandallo Total]],2,FALSE) -> 0 | C8: =VLOOKUP(Tabla57[[#This Row],[Id]],Tabla5[[Id]:[Escandallo Total]],4,FALSE) -> 0 | D8: =Tabla57[[#This Row],[Escandallo Total]]*Datos!$B$2+Tabla57[[#This Row],[Escandallo Total]] -> 0 | E8: =Tabla57[[#This Row],[Beneficio]]*Datos!$B$1+Tabla57[[#This Row],[Beneficio]] -> 0
A9: 7 | B9: =VLOOKUP(Tabla57[[#This Row],[Id]],Tabla5[[Id]:[Escandallo Total]],2,FALSE) -> 0 | C9: =VLOOKUP(Tabla57[[#This Row],[Id]],Tabla5[[Id]:[Escandallo Total]],4,FALSE) -> 0 | D9: =Tabla57[[#This Row],[Escandallo Total]]*Datos!$B$2+Tabla57[[#This Row],[Escandallo Total]] -> 0 | E9: =Tabla57[[#This Row],[Beneficio]]*Datos!$B$1+Tabla57[[#This Row],[Beneficio]] -> 0
A10: 8 | B10: =VLOOKUP(Tabla57[[#This Row],[Id]],Tabla5[[Id]:[Escandallo Total]],2,FALSE) -> 0 | C10: =VLOOKUP(Tabla57[[#This Row],[Id]],Tabla5[[Id]:[Escandallo Total]],4,FALSE) -> 0 | D10: =Tabla57[[#This Row],[Escandallo Total]]*Datos!$B$2+Tabla57[[#This Row],[Escandallo Total]] -> 0 | E10: =Tabla57[[#This Row],[Beneficio]]*Datos!$B$1+Tabla57[[#This Row],[Beneficio]] -> 0
A11: 9 | B11: =VLOOKUP(Tabla57[[#This Row],[Id]],Tabla5[[Id]:[Escandallo Total]],2,FALSE) -> 0 | C11: =VLOOKUP(Tabla57[[#This Row],[Id]],Tabla5[[Id]:[Escandallo Total]],4,FALSE) -> 0 | D11: =Tabla57[[#This Row],[Escandallo Total]]*Datos!$B$2+Tabla57[[#This Row],[Escandallo Total]] -> 0 | E11: =Tabla57[[#This Row],[Beneficio]]*Datos!$B$1+Tabla57[[#This Row],[Beneficio]] -> 0
A12: 10 | B12: =VLOOKUP(Tabla57[[#This Row],[Id]],Tabla5[[Id]:[Escandallo Total]],2,FALSE) -> 0 | C12: =VLOOKUP(Tabla57[[#This Row],[Id]],Tabla5[[Id]:[Escandallo Total]],4,FALSE) -> 0 | D12: =Tabla57[[#This Row],[Escandallo Total]]*Datos!$B$2+Tabla57[[#This Row],[Escandallo Total]] -> 0 | E12: =Tabla57[[#This Row],[Beneficio]]*Datos!$B$1+Tabla57[[#This Row],[Beneficio]] -> 0
A13: 11 | B13: =VLOOKUP(Tabla57[[#This Row],[Id]],Tabla5[[Id]:[Escandallo Total]],2,FALSE) -> 0 | C13: =VLOOKUP(Tabla57[[#This Row],[Id]],Tabla5[[Id]:[Escandallo Total]],4,FALSE) -> 0 | D13: =Tabla57[[#This Row],[Escandallo Total]]*Datos!$B$2+Tabla57[[#This Row],[Escandallo Total]] -> 0 | E13: =Tabla57[[#This Row],[Beneficio]]*Datos!$B$1+Tabla57[[#This Row],[Beneficio]] -> 0
A14: 12 | B14: =VLOOKUP(Tabla57[[#This Row],[Id]],Tabla5[[Id]:[Escandallo Total]],2,FALSE) -> 0 | C14: =VLOOKUP(Tabla57[[#This Row],[Id]],Tabla5[[Id]:[Escandallo Total]],4,FALSE) -> 0 | D14: =Tabla57[[#This Row],[Escandallo Total]]*Datos!$B$2+Tabla57[[#This Row],[Escandallo Total]] -> 0 | E14: =Tabla57[[#This Row],[Beneficio]]*Datos!$B$1+Tabla57[[#This Row],[Beneficio]] -> 0
A15: 13 | B15: =VLOOKUP(Tabla57[[#This Row],[Id]],Tabla5[[Id]:[Escandallo Total]],2,FALSE) -> 0 | C15: =VLOOKUP(Tabla57[[#This Row],[Id]],Tabla5[[Id]:[Escandallo Total]],4,FALSE) -> 0 | D15: =Tabla57[[#This Row],[Escandallo Total]]*Datos!$B$2+Tabla57[[#This Row],[Escandallo Total]] -> 0 | E15: =Tabla57[[#This Row],[Beneficio]]*Datos!$B$1+Tabla57[[#This Row],[Beneficio]] -> 0
... A60: 58 | B60: =VLOOKUP(Tabla57[[#This Row],[Id]],Tabla5[[Id]:[Escandallo Total]],2,FALSE) -> 0 | C60: =VLOOKUP(Tabla57[[#This Row],[Id]],Tabla5[[Id]:[Escandallo Total]],4,FALSE) -> 0 | D60: =Tabla57[[#This Row],[Escandallo Total]]*Datos!$B$2+Tabla57[[#This Row],[Escandallo Total]] -> 0 | E60: =Tabla57[[#This Row],[Beneficio]]*Datos!$B$1+Tabla57[[#This Row],[Beneficio]] -> 0

Sheet Servicios
A1: Id | B1: Servicio | C1: Minutos | D1: Escandallo Total | E1: Gastos Generales | F1: Persona | G1: Coste Persona | H1: Producto 1 | I1: Cantidad 1 | J1: Coste 1 | K1: Producto 2 | L1: Cantidad 2 | M1: Coste 2 | N1: Producto 3 | O1: Cantidad 3 | P1: Coste 3 | Q1: Producto 4 | R1: Cantidad 4 | S1: Coste 4 | T1: Producto 5 | U1: Cantidad 5 | V1: Coste 5 | W1: Producto 6 | X1: Cantidad 6 | Y1: Coste 6 | Z1: Producto 7 | AA1: Cantidad 7 | AB1: Coste 7 | AC1: Producto 8 | AD1: Cantidad 8 | AE1: Coste 8 | AF1: Producto 9 | AG1: Cantidad 9 | AH1: Coste 9 | AI1: Producto 10 | AJ1: Cantidad 10 | AK1: Coste 10 | AL1: Producto 11 | AM1: Cantidad 11 | AN1: Coste 11 | AO1: Producto 12 | AP1: Cantidad 12 | AQ1: Coste 12 | AR1: Producto 13 | AS1: Cantidad 13 | AT1: Coste 13 | AU1: Producto 14 | AV1: Cantidad 14 | AW1: Coste 14 | AX1: Producto 15 | AY1: Cantidad 15 | AZ1: Coste 15 | BA1: Producto 16 | BB1: Cantidad 16 | BC1: Coste 16 | BD1: Producto 17 | BE1: Cantidad 17 | BF1: Coste 17 | BG1: Producto 18 | BH1: Cantidad 18 | BI1: Coste 18 | BJ1: Producto 19 | BK1: Cantidad 19 | BL1: Coste 19 | BM1: Producto 20 | BN1: Cantidad 20 | BO1: Coste 20 | BP1: Producto 21 | BQ1: Cantidad 21 | BR1: Coste 21 | BS1: Producto 22 | BT1: Cantidad 22 | BU1: Coste 22 | BV1: Producto 23 | BW1: Cantidad 23 | BX1: Coste 23 | BY1: Producto 24 | BZ1: Cantidad 24 | CA1: Coste 24 | CB1: Producto 25 | CC1: Cantidad 25 | CD1: Coste 25 | CE1: Producto 26 | CF1: Cantidad 26 | CG1: Coste 26 | CH1: Producto 27 | CI1: Cantidad 27 | CJ1: Coste 27 | CK1: Producto 28 | CL1: Cantidad 28 | CM1: Coste 28 | CN1: Producto 29 | CO1: Cantidad 29 | CP1: Coste 29 | CQ1: Producto 30 | CR1: Cantidad 30 | CS1: Coste 30
A2: 0 | B2: Prueba | C2: 60 | D2: =Tabla5[[#This Row],[Gastos Generales]]+Tabla5[[#This Row],[Coste Persona]]+Tabla5[[#This Row],[Coste 1]]+Tabla5[[#This Row],[Coste 2]]+Tabla5[[#This Row],[Coste 3]]+Tabla5[[#This Row],[Coste 4]]+Tabla5[[#This Row],[Coste 5]]+Tabla5[[#This Row],[Coste 6]]+Tabla5[[#This Row],[Coste 7]]+Tabla5[[#This Row],[Coste 8]]+Tabla5[[#This Row],[Coste 9]]+Tabla5[[#This Row],[Coste 10]]+Tabla5[[#This Row],[Coste 11]]+Tabla5[[#This Row],[Coste 12]]+Tabla5[[#This Row],[Coste 13]]+Tabla5[[#This Row],[Coste 14]]+Tabla5[[#This Row],[Coste 15]]+Tabla5[[#This Row],[Coste 16]]+Tabla5[[#This Row],[Coste 17]]+Tabla5[[#This Row],[Coste 18]]+Tabla5[[#This Row],[Coste 19]]+Tabla5[[#This Row],[Coste 20]]+Tabla5[[#This Row],[Coste 21]]+Tabla5[[#This Row],[Coste 22]]+Tabla5[[#This Row],[Coste 23]]+Tabla5[[#This Row],[Coste 24]]+Tabla5[[#This Row],[Coste 25]]+Tabla5[[#This Row],[Coste 26]]+Tabla5[[#This Row],[Coste 27]]+Tabla5[[#This Row],[Coste 28]]+Tabla5[[#This Row],[Coste 29]]+Tabla5[[#This Row],[Coste 30]] -> 85.724731 | E2: =Tabla5[[#This Row],[Minutos]]*Tabla13[[#Totals],[Precio Unitario]] -> 4.9715909 | F2: Técnico | G2: =IFERROR(VLOOKUP(Tabla5[[#This Row],[Persona]],Tabla1[[Nombre]:[Ud]],7,FALSE) *Tabla5[[#This Row],[Minutos]],0) -> 11.25 | H2: Cleasing Milk | I2: 20 | J2: =IFERROR(VLOOKUP(Tabla5[[#This Row],[Producto 1]],Tabla3[[Nombre]:[Ud]],5,FALSE)*Tabla5[[#This Row],[Cantidad 1]],0) -> 1.3804 | K2: Cleasing milk | L2: 21 | M2: =IFERROR(VLOOKUP(Tabla5[[#This Row],[Producto 2]],Tabla3[[Nombre]:[Ud]],5,FALSE)*Tabla5[[#This Row],[Cantidad 2]],0) -> 1.44942 | N2: Cleasing milk | O2: 21 | P2: =IFERROR(VLOOKUP(Tabla5[[#This Row],[Producto 3]],Tabla3[[Nombre]:[Ud]],5,FALSE)*Tabla5[[#This Row],[Cantidad 3]],0) -> 1.44942 | Q2: Cleasing milk | R2: 22 | S2: =IFERROR(VLOOKUP(Tabla5[[#This Row],[Producto 4]],Tabla3[[Nombre]:[Ud]],5,FALSE)*Tabla5[[#This Row],[Cantidad 4]],0) -> 1.51844 | T2: Cleasing milk | U2: 23 | V2: =IFERROR(VLOOKUP(Tabla5[[#This Row],[Producto 5]],Tabla3[[Nombre]:[Ud]],5,FALSE)*Tabla5[[#This Row],[Cantidad 5]],0) -> 1.58746 | W2: Cleasing milk | X2: 24 | Y2: =IFERROR(VLOOKUP(Tabla5[[#This Row],[Producto 6]],Tabla3[[Nombre]:[Ud]],5,FALSE)*Tabla5[[#This Row],[Cantidad 6]],0) -> 1.65648 | Z2: Cleasing milk | AA2: 25 | AB2: =IFERROR(VLOOKUP(Tabla5[[#This Row],[Producto 7]],Tabla3[[Nombre]:[Ud]],5,FALSE)*Tabla5[[#This Row],[Cantidad 7]],0) -> 1.7255 | AC2: Cleasing milk | AD2: 26 | AE2: =IFERROR(VLOOKUP(Tabla5[[#This Row],[Producto 8]],Tabla3[[Nombre]:[Ud]],5,FALSE)*Tabla5[[#This Row],[Cantidad 8]],0) -> 1.79452 | AF2: Cleasing milk | AG2: 27 | AH2: =IFERROR(VLOOKUP(Tabla5[[#This Row],[Producto 9]],Tabla3[[Nombre]:[Ud]],5,FALSE)*Tabla5[[#This Row],[Cantidad 9]],0) -> 1.86354 | AI2: Cleasing milk | AJ2: 28 | AK2: =IFERROR(VLOOKUP(Tabla5[[#This Row],[Producto 10]],Tabla3[[Nombre]:[Ud]],5,FALSE)*Tabla5[[#This Row],[Cantidad 10]],0) -> 1.93256 | AL2: Cleasing milk | AM2: 29 | AN2: =IFERROR(VLOOKUP(Tabla5[[#This Row],[Producto 11]],Tabla3[[Nombre]:[Ud]],5,FALSE)*Tabla5[[#This Row],[Cantidad 11]],0) -> 2.00158 | AO2: Cleasing milk | AP2: 30 | AQ2: =IFERROR(VLOOKUP(Tabla5[[#This Row],[Producto 12]],Tabla3[[Nombre]:[Ud]],5,FALSE)*Tabla5[[#This Row],[Cantidad 12]],0) -> 2.0706 | AR2: Cleasing milk | AS2: 31 | AT2: =IFERROR(VLOOKUP(Tabla5[[#This Row],[Producto 13]],Tabla3[[Nombre]:[Ud]],5,FALSE)*Tabla5[[#This Row],[Cantidad 13]],0) -> 2.13962 | AU2: Cleasing milk | AV2: 32 | AW2: =IFERROR(VLOOKUP(Tabla5[[#This Row],[Producto 14]],Tabla3[[Nombre]:[Ud]],5,FALSE)*Tabla5[[#This Row],[Cantidad 14]],0) -> 2.20864 | AX2: Cleasing milk | AY2: 33 | AZ2: =IFERROR(VLOOKUP(Tabla5[[#This Row],[Producto 15]],Tabla3[[Nombre]:[Ud]],5,FALSE)*Tabla5[[#This Row],[Cantidad 15]],0) -> 2.27766 | BA2: Cleasing milk | BB2: 34 | BC2: =IFERROR(VLOOKUP(Tabla5[[#This Row],[Producto 16]],Tabla3[[Nombre]:[Ud]],5,FALSE)*Tabla5[[#This Row],[Cantidad 16]],0) -> 2.34668 | BD2: Cleasing milk | BE2: 35 | BF2: =IFERROR(VLOOKUP(Tabla5[[#This Row],[Producto 17]],Tabla3[[Nombre]:[Ud]],5,FALSE)*Tabla5[[#This Row],[Cantidad 17]],0) -> 2.4157 | BG2: Cleasing milk | BH2: 36 | BI2: =IFERROR(VLOOKUP(Tabla5[[#This Row],[Producto 18]],Tabla3[[Nombre]:[Ud]],5,FALSE)*Tabla5[[#This Row],[Cantidad 18]],0) -> 2.48472 | BJ2: Cleasing milk | BK2: 37 | BL2: =IFERROR(VLOOKUP(Tabla5[[#This Row],[Producto 19]],Tabla3[[Nombre]:[Ud]],5,FALSE)*Tabla5[[#This Row],[Cantidad 19]],0) -> 2.55374 | BM2: Cleasing milk | BN2: 38 | BO2: =IFERROR(VLOOKUP(Tabla5[[#This Row],[Producto 20]],Tabla3[[Nombre]:[Ud]],5,FALSE)*Tabla5[[#This Row],[Cantidad 20]],0) -> 2.62276 | BP2: Cleasing milk | BQ2: 39 | BR2: =IFERROR(VLOOKUP(Tabla5[[#This Row],[Producto 21]],Tabla3[[Nombre]:[Ud]],5,FALSE)*Tabla5[[#This Row],[Cantidad 21]],0) -> 2.69178 | BS2: Cleasing milk | BT2: 40 | BU2: =IFERROR(VLOOKUP(Tabla5[[#This Row],[Producto 22]],Tabla3[[Nombre]:[Ud]],5,FALSE)*Tabla5[[#This Row],[Cantidad 22]],0) -> 2.7608 | BV2: Cleasing milk | BW2: 41 | BX2: =IFERROR(VLOOKUP(Tabla5[[#This Row],[Producto 23]],Tabla3[[Nombre]:[Ud]],5,FALSE)*Tabla5[[#This Row],[Cantidad 23]],0) -> 2.82982 | BY2: Cleasing milk | BZ2: 42 | CA2: =IFERROR(VLOOKUP(Tabla5[[#This Row],[Producto 24]],Tabla3[[Nombre]:[Ud]],5,FALSE)*Tabla5[[#This Row],[Cantidad 24]],0) -> 2.89884 | CB2: Cleasing milk | CC2: 43 | CD2: =IFERROR(VLOOKUP(Tabla5[[#This Row],[Producto 25]],Tabla3[[Nombre]:[Ud]],5,FALSE)*Tabla5[[#This Row],[Cantidad 25]],0) -> 2.96786 | CE2: Cleasing milk | CF2: 44 | CG2: =IFERROR(VLOOKUP(Tabla5[[#This Row],[Producto 26]],Tabla3[[Nombre]:[Ud]],5,FALSE)*Tabla5[[#This Row],[Cantidad 26]],0) -> 3.03688 | CH2: Cleasing milk | CI2: 45 | CJ2: =IFERROR(VLOOKUP(Tabla5[[#This Row],[Producto 27]],Tabla3[[Nombre]:[Ud]],5,FALSE)*Tabla5[[#This Row],[Cantidad 27]],0) -> 3.1059 | CK2: Cleasing milk | CL2: 46 | CM2: =IFERROR(VLOOKUP(Tabla5[[#This Row],[Producto 28]],Tabla3[[Nombre]:[Ud]],5,FALSE)*Tabla5[[#This Row],[Cantidad 28]],0) -> 3.17492 | CN2: Cleasing milk | CO2: 47 | CP2: =IFERROR(VLOOKUP(Tabla5[[#This Row],[Producto 29]],Tabla3[[Nombre]:[Ud]],5,FALSE)*Tabla5[[#This Row],[Cantidad 29]],0) -> 3.24394 | CQ2: Cleasing milk | CR2: 48 | CS2: =IFERROR(VLOOKUP(Tabla5[[#This Row],[Producto 30]],Tabla3[[Nombre]:[Ud]],5,FALSE)*Tabla5[[#This Row],[Cantidad 30]],0) -> 3.31296
A3: 1 | B3: Mesodermolifting | C3: 60 | D3: =Tabla5[[#This Row],[Gastos Generales]]+Tabla5[[#This Row],[Coste Persona]]+Tabla5[[#This Row],[Coste 1]]+Tabla5[[#This Row],[Coste 2]]+Tabla5[[#This Row],[Coste 3]]+Tabla5[[#This Row],[Coste 4]]+Tabla5[[#This Row],[Coste 5]]+Tabla5[[#This Row],[Coste 6]]+Tabla5[[#This Row],[Coste 7]]+Tabla5[[#This Row],[Coste 8]]+Tabla5[[#This Row],[Coste 9]]+Tabla5[[#This Row],[Coste 10]]+Tabla5[[#This Row],[Coste 11]]+Tabla5[[#This Row],[Coste 12]]+Tabla5[[#This Row],[Coste 13]]+Tabla5[[#This Row],[Coste 14]]+Tabla5[[#This Row],[Coste 15]]+Tabla5[[#This Row],[Coste 16]]+Tabla5[[#This Row],[Coste 17]]+Tabla5[[#This Row],[Coste 18]]+Tabla5[[#This Row],[Coste 19]]+Tabla5[[#This Row],[Coste 20]]+Tabla5[[#This Row],[Coste 21]]+Tabla5[[#This Row],[Coste 22]]+Tabla5[[#This Row],[Coste 23]]+Tabla5[[#This Row],[Coste 24]]+Tabla5[[#This Row],[Coste 25]]+Tabla5[[#This Row],[Coste 26]]+Tabla5[[#This Row],[Coste 27]]+Tabla5[[#This Row],[Coste 28]]+Tabla5[[#This Row],[Coste 29]]+Tabla5[[#This Row],[Coste 30]] -> 34.712457 | E3: =Tabla5[[#This Row],[Minutos]]*Tabla13[[#Totals],[Precio Unitario]] -> 4.9715909 | F3: Encargado | G3: =IFERROR(VLOOKUP(Tabla5[[#This Row],[Persona]],Tabla1[[Nombre]:[Ud]],7,FALSE) *Tabla5[[#This Row],[Minutos]],0) -> 16.363636 | H3: Cleasing Milk | I3: 4 | J3: =IFERROR(VLOOKUP(Tabla5[[#This Row],[Producto 1]],Tabla3[[Nombre]:[Ud]],5,FALSE)*Tabla5[[#This Row],[Cantidad 1]],0) -> 0.27608 | K3: Facial Tonic | L3: 2 | M3: =IFERROR(VLOOKUP(Tabla5[[#This Row],[Producto 2]],Tabla3[[Nombre]:[Ud]],5,FALSE)*Tabla5[[#This Row],[Cantidad 2]],0) -> 0.154 | N3: Salycili Removing | O3: 1 | P3: =IFERROR(VLOOKUP(Tabla5[[#This Row],[Producto 3]],Tabla3[[Nombre]:[Ud]],5,FALSE)*Tabla5[[#This Row],[Cantidad 3]],0) -> 0.7058 | Q3: Gamma lift | R3: 2 | S3: =IFERROR(VLOOKUP(Tabla5[[#This Row],[Producto 4]],Tabla3[[Nombre]:[Ud]],5,FALSE)*Tabla5[[#This Row],[Cantidad 4]],0) -> 7.6 | T3: Dexpanthenol | U3: 2.5 | V3: =IFERROR(VLOOKUP(Tabla5[[#This Row],[Producto 5]],Tabla3[[Nombre]:[Ud]],5,FALSE)*Tabla5[[#This Row],[Cantidad 5]],0) -> 1.2915 | W3: DMAE | X3: 2.5 | Y3: =IFERROR(VLOOKUP(Tabla5[[#This Row],[Producto 6]],Tabla3[[Nombre]:[Ud]],5,FALSE)*Tabla5[[#This Row],[Cantidad 6]],0) -> 1.055 | Z3: Collagen Pyruvate | AA3: 1 | AB3: =IFERROR(VLOOKUP(Tabla5[[#This Row],[Producto 7]],Tabla3[[Nombre]:[Ud]],5,FALSE)*Tabla5[[#This Row],[Cantidad 7]],0) -> 1.1955 | AC3: HydraFace | AD3: 1 | AE3: =IFERROR(VLOOKUP(Tabla5[[#This Row],[Producto 8]],Tabla3[[Nombre]:[Ud]],5,FALSE)*Tabla5[[#This Row],[Cantidad 8]],0) -> 0.2182 | AF3: Protección Solar | AG3: 1 | AH3: =IFERROR(VLOOKUP(Tabla5[[#This Row],[Producto 9]],Tabla3[[Nombre]:[Ud]],5,FALSE)*Tabla5[[#This Row],[Cantidad 9]],0) -> 0.33035 | AI3: Oxigel | AJ3: 3 | AK3: =IFERROR(VLOOKUP(Tabla5[[#This Row],[Producto 10]],Tabla3[[Nombre]:[Ud]],5,FALSE)*Tabla5[[#This Row],[Cantidad 10]],0) -> 0.5508 | AN3: =IFERROR(VLOOKUP(Tabla5[[#This Row],[Producto 11]],Tabla3[[Nombre]:[Ud]],5,FALSE)*Tabla5[[#This Row],[Cantidad 11]],0) -> 0 | AQ3: =IFERROR(VLOOKUP(Tabla5[[#This Row],[Producto 12]],Tabla3[[Nombre]:[Ud]],5,FALSE)*Tabla5[[#This Row],[Cantidad 12]],0) -> 0 | AT3: =IFERROR(VLOOKUP(Tabla5[[#This Row],[Producto 13]],Tabla3[[Nombre]:[Ud]],5,FALSE)*Tabla5[[#This Row],[Cantidad 13]],0) -> 0 | AW3: =IFERROR(VLOOKUP(Tabla5[[#This Row],[Producto 14]],Tabla3[[Nombre]:[Ud]],5,FALSE)*Tabla5[[#This Row],[Cantidad 14]],0) -> 0 | AZ3: =IFERROR(VLOOKUP(Tabla5[[#This Row],[Producto 15]],Tabla3[[Nombre]:[Ud]],5,FALSE)*Tabla5[[#This Row],[Cantidad 15]],0) -> 0 | BC3: =IFERROR(VLOOKUP(Tabla5[[#This Row],[Producto 16]],Tabla3[[Nombre]:[Ud]],5,FALSE)*Tabla5[[#This Row],[Cantidad 16]],0) -> 0 | BF3: =IFERROR(VLOOKUP(Tabla5[[#This Row],[Producto 17]],Tabla3[[Nombre]:[Ud]],5,FALSE)*Tabla5[[#This Row],[Cantidad 17]],0) -> 0 | BI3: =IFERROR(VLOOKUP(Tabla5[[#This Row],[Producto 18]],Tabla3[[Nombre]:[Ud]],5,FALSE)*Tabla5[[#This Row],[Cantidad 18]],0) -> 0 | BL3: =IFERROR(VLOOKUP(Tabla5[[#This Row],[Producto 19]],Tabla3[[Nombre]:[Ud]],5,FALSE)*Tabla5[[#This Row],[Cantidad 19]],0) -> 0 | BO3: =IFERROR(VLOOKUP(Tabla5[[#This Row],[Producto 20]],Tabla3[[Nombre]:[Ud]],5,FALSE)*Tabla5[[#This Row],[Cantidad 20]],0) -> 0 | BR3: =IFERROR(VLOOKUP(Tabla5[[#This Row],[Producto 21]],Tabla3[[Nombre]:[Ud]],5,FALSE)*Tabla5[[#This Row],[Cantidad 21]],0) -> 0 | BU3: =IFERROR(VLOOKUP(Tabla5[[#This Row],[Producto 22]],Tabla3[[Nombre]:[Ud]],5,FALSE)*Tabla5[[#This Row],[Cantidad 22]],0) -> 0 | BX3: =IFERROR(VLOOKUP(Tabla5[[#This Row],[Producto 23]],Tabla3[[Nombre]:[Ud]],5,FALSE)*Tabla5[[#This Row],[Cantidad 23]],0) -> 0 | CA3: =IFERROR(VLOOKUP(Tabla5[[#This Row],[Producto 24]],Tabla3[[Nombre]:[Ud]],5,FALSE)*Tabla5[[#This Row],[Cantidad 24]],0) -> 0 | CD3: =IFERROR(VLOOKUP(Tabla5[[#This Row],[Producto 25]],Tabla3[[Nombre]:[Ud]],5,FALSE)*Tabla5[[#This Row],[Cantidad 25]],0) -> 0 | CG3: =IFERROR(VLOOKUP(Tabla5[[#This Row],[Producto 26]],Tabla3[[Nombre]:[Ud]],5,FALSE)*Tabla5[[#This Row],[Cantidad 26]],0) -> 0 | CJ3: =IFERROR(VLOOKUP(Tabla5[[#This Row],[Producto 27]],Tabla3[[Nombre]:[Ud]],5,FALSE)*Tabla5[[#This Row],[Cantidad 27]],0) -> 0 | CM3: =IFERROR(VLOOKUP(Tabla5[[#This Row],[Producto 28]],Tabla3[[Nombre]:[Ud]],5,FALSE)*Tabla5[[#This Row],[Cantidad 28]],0) -> 0 | CP3: =IFERROR(VLOOKUP(Tabla5[[#This Row],[Producto 29]],Tabla3[[Nombre]:[Ud]],5,FALSE)*Tabla5[[#This Row],[Cantidad 29]],0) -> 0 | CS3: =IFERROR(VLOOKUP(Tabla5[[#This Row],[Producto 30]],Tabla3[[Nombre]:[Ud]],5,FALSE)*Tabla5[[#This Row],[Cantidad 30]],0) -> 0
A4: 2 | D4: =Tabla5[[#This Row],[Gastos Generales]]+Tabla5[[#This Row],[Coste Persona]]+Tabla5[[#This Row],[Coste 1]]+Tabla5[[#This Row],[Coste 2]]+Tabla5[[#This Row],[Coste 3]]+Tabla5[[#This Row],[Coste 4]]+Tabla5[[#This Row],[Coste 5]]+Tabla5[[#This Row],[Coste 6]]+Tabla5[[#This Row],[Coste 7]]+Tabla5[[#This Row],[Coste 8]]+Tabla5[[#This Row],[Coste 9]]+Tabla5[[#This Row],[Coste 10]]+Tabla5[[#This Row],[Coste 11]]+Tabla5[[#This Row],[Coste 12]]+Tabla5[[#This Row],[Coste 13]]+Tabla5[[#This Row],[Coste 14]]+Tabla5[[#This Row],[Coste 15]]+Tabla5[[#This Row],[Coste 16]]+Tabla5[[#This Row],[Coste 17]]+Tabla5[[#This Row],[Coste 18]]+Tabla5[[#This Row],[Coste 19]]+Tabla5[[#This Row],[Coste 20]]+Tabla5[[#This Row],[Coste 21]]+Tabla5[[#This Row],[Coste 22]]+Tabla5[[#This Row],[Coste 23]]+Tabla5[[#This Row],[Coste 24]]+Tabla5[[#This Row],[Coste 25]]+Tabla5[[#This Row],[Coste 26]]+Tabla5[[#This Row],[Coste 27]]+Tabla5[[#This Row],[Coste 28]]+Tabla5[[#This Row],[Coste 29]]+Tabla5[[#This Row],[Coste 30]] -> 0 | E4: =Tabla5[[#This Row],[Minutos]]*Tabla13[[#Totals],[Precio Unitario]] -> 0 | G4: =IFERROR(VLOOKUP(Tabla5[[#This Row],[Persona]],Tabla1[[Nombre]:[Ud]],7,FALSE) *Tabla5[[#This Row],[Minutos]],0) -> 0 | J4: =IFERROR(VLOOKUP(Tabla5[[#This Row],[Producto 1]],Tabla3[[Nombre]:[Ud]],5,FALSE)*Tabla5[[#This Row],[Cantidad 1]],0) -> 0 | M4: =IFERROR(VLOOKUP(Tabla5[[#This Row],[Producto 2]],Tabla3[[Nombre]:[Ud]],5,FALSE)*Tabla5[[#This Row],[Cantidad 2]],0) -> 0 | P4: =IFERROR(VLOOKUP(Tabla5[[#This Row],[Producto 3]],Tabla3[[Nombre]:[Ud]],5,FALSE)*Tabla5[[#This Row],[Cantidad 3]],0) -> 0 | S4: =IFERROR(VLOOKUP(Tabla5[[#This Row],[Producto 4]],Tabla3[[Nombre]:[Ud]],5,FALSE)*Tabla5[[#This Row],[Cantidad 4]],0) -> 0 | V4: =IFERROR(VLOOKUP(Tabla5[[#This Row],[Producto 5]],Tabla3[[Nombre]:[Ud]],5,FALSE)*Tabla5[[#This Row],[Cantidad 5]],0) -> 0 | Y4: =IFERROR(VLOOKUP(Tabla5[[#This Row],[Producto 6]],Tabla3[[Nombre]:[Ud]],5,FALSE)*Tabla5[[#This Row],[Cantidad 6]],0) -> 0 | AB4: =IFERROR(VLOOKUP(Tabla5[[#This Row],[Producto 7]],Tabla3[[Nombre]:[Ud]],5,FALSE)*Tabla5[[#This Row],[Cantidad 7]],0) -> 0 | AE4: =IFERROR(VLOOKUP(Tabla5[[#This Row],[Producto 8]],Tabla3[[Nombre]:[Ud]],5,FALSE)*Tabla5[[#This Row],[Cantidad 8]],0) -> 0 | AH4: =IFERROR(VLOOKUP(Tabla5[[#This Row],[Producto 9]],Tabla3[[Nombre]:[Ud]],5,FALSE)*Tabla5[[#This Row],[Cantidad 9]],0) -> 0 | AK4: =IFERROR(VLOOKUP(Tabla5[[#This Row],[Producto 10]],Tabla3[[Nombre]:[Ud]],5,FALSE)*Tabla5[[#This Row],[Cantidad 10]],0) -> 0 | AN4: =IFERROR(VLOOKUP(Tabla5[[#This Row],[Producto 11]],Tabla3[[Nombre]:[Ud]],5,FALSE)*Tabla5[[#This Row],[Cantidad 11]],0) -> 0 | AQ4: =IFERROR(VLOOKUP(Tabla5[[#This Row],[Producto 12]],Tabla3[[Nombre]:[Ud]],5,FALSE)*Tabla5[[#This Row],[Cantidad 12]],0) -> 0 | AT4: =IFERROR(VLOOKUP(Tabla5[[#This Row],[Producto 13]],Tabla3[[Nombre]:[Ud]],5,FALSE)*Tabla5[[#This Row],[Cantidad 13]],0) -> 0 | AW4: =IFERROR(VLOOKUP(Tabla5[[#This Row],[Producto 14]],Tabla3[[Nombre]:[Ud]],5,FALSE)*Tabla5[[#This Row],[Cantidad 14]],0) -> 0 | AZ4: =IFERROR(VLOOKUP(Tabla5[[#This Row],[Producto 15]],Tabla3[[Nombre]:[Ud]],5,FALSE)*Tabla5[[#This Row],[Cantidad 15]],0) -> 0 | BC4: =IFERROR(VLOOKUP(Tabla5[[#This Row],[Producto 16]],Tabla3[[Nombre]:[Ud]],5,FALSE)*Tabla5[[#This Row],[Cantidad 16]],0) -> 0 | BF4: =IFERROR(VLOOKUP(Tabla5[[#This Row],[Producto 17]],Tabla3[[Nombre]:[Ud]],5,FALSE)*Tabla5[[#This Row],[Cantidad 17]],0) -> 0 | BI4: =IFERROR(VLOOKUP(Tabla5[[#This Row],[Producto 18]],Tabla3[[Nombre]:[Ud]],5,FALSE)*Tabla5[[#This Row],[Cantidad 18]],0) -> 0 | BL4: =IFERROR(VLOOKUP(Tabla5[[#This Row],[Producto 19]],Tabla3[[Nombre]:[Ud]],5,FALSE)*Tabla5[[#This Row],[Cantidad 19]],0) -> 0 | BO4: =IFERROR(VLOOKUP(Tabla5[[#This Row],[Producto 20]],Tabla3[[Nombre]:[Ud]],5,FALSE)*Tabla5[[#This Row],[Cantidad 20]],0) -> 0 | BR4: =IFERROR(VLOOKUP(Tabla5[[#This Row],[Producto 21]],Tabla3[[Nombre]:[Ud]],5,FALSE)*Tabla5[[#This Row],[Cantidad 21]],0) -> 0 | BU4: =IFERROR(VLOOKUP(Tabla5[[#This Row],[Producto 22]],Tabla3[[Nombre]:[Ud]],5,FALSE)*Tabla5[[#This Row],[Cantidad 22]],0) -> 0 | BX4: =IFERROR(VLOOKUP(Tabla5[[#This Row],[Producto 23]],Tabla3[[Nombre]:[Ud]],5,FALSE)*Tabla5[[#This Row],[Cantidad 23]],0) -> 0 | CA4: =IFERROR(VLOOKUP(Tabla5[[#This Row],[Producto 24]],Tabla3[[Nombre]:[Ud]],5,FALSE)*Tabla5[[#This Row],[Cantidad 24]],0) -> 0 | CD4: =IFERROR(VLOOKUP(Tabla5[[#This Row],[Producto 25]],Tabla3[[Nombre]:[Ud]],5,FALSE)*Tabla5[[#This Row],[Cantidad 25]],0) -> 0 | CG4: =IFERROR(VLOOKUP(Tabla5[[#This Row],[Producto 26]],Tabla3[[Nombre]:[Ud]],5,FALSE)*Tabla5[[#This Row],[Cantidad 26]],0) -> 0 | CJ4: =IFERROR(VLOOKUP(Tabla5[[#This Row],[Producto 27]],Tabla3[[Nombre]:[Ud]],5,FALSE)*Tabla5[[#This Row],[Cantidad 27]],0) -> 0 | CM4: =IFERROR(VLOOKUP(Tabla5[[#This Row],[Producto 28]],Tabla3[[Nombre]:[Ud]],5,FALSE)*Tabla5[[#This Row],[Cantidad 28]],0) -> 0 | CP4: =IFERROR(VLOOKUP(Tabla5[[#This Row],[Producto 29]],Tabla3[[Nombre]:[Ud]],5,FALSE)*Tabla5[[#This Row],[Cantidad 29]],0) -> 0 | CS4: =IFERROR(VLOOKUP(Tabla5[[#This Row],[Producto 30]],Tabla3[[Nombre]:[Ud]],5,FALSE)*Tabla5[[#This Row],[Cantidad 30]],0) -> 0
A5: 3 | D5: =Tabla5[[#This Row],[Gastos Generales]]+Tabla5[[#This Row],[Coste Persona]]+Tabla5[[#This Row],[Coste 1]]+Tabla5[[#This Row],[Coste 2]]+Tabla5[[#This Row],[Coste 3]]+Tabla5[[#This Row],[Coste 4]]+Tabla5[[#This Row],[Coste 5]]+Tabla5[[#This Row],[Coste 6]]+Tabla5[[#This Row],[Coste 7]]+Tabla5[[#This Row],[Coste 8]]+Tabla5[[#This Row],[Coste 9]]+Tabla5[[#This Row],[Coste 10]]+Tabla5[[#This Row],[Coste 11]]+Tabla5[[#This Row],[Coste 12]]+Tabla5[[#This Row],[Coste 13]]+Tabla5[[#This Row],[Coste 14]]+Tabla5[[#This Row],[Coste 15]]+Tabla5[[#This Row],[Coste 16]]+Tabla5[[#This Row],[Coste 17]]+Tabla5[[#This Row],[Coste 18]]+Tabla5[[#This Row],[Coste 19]]+Tabla5[[#This Row],[Coste 20]]+Tabla5[[#This Row],[Coste 21]]+Tabla5[[#This Row],[Coste 22]]+Tabla5[[#This Row],[Coste 23]]+Tabla5[[#This Row],[Coste 24]]+Tabla5[[#This Row],[Coste 25]]+Tabla5[[#This Row],[Coste 26]]+Tabla5[[#This Row],[Coste 27]]+Tabla5[[#This Row],[Coste 28]]+Tabla5[[#This Row],[Coste 29]]+Tabla5[[#This Row],[Coste 30]] -> 0 | E5: =Tabla5[[#This Row],[Minutos]]*Tabla13[[#Totals],[Precio Unitario]] -> 0 | G5: =IFERROR(VLOOKUP(Tabla5[[#This Row],[Persona]],Tabla1[[Nombre]:[Ud]],7,FALSE) *Tabla5[[#This Row],[Minutos]],0) -> 0 | J5: =IFERROR(VLOOKUP(Tabla5[[#This Row],[Producto 1]],Tabla3[[Nombre]:[Ud]],5,FALSE)*Tabla5[[#This Row],[Cantidad 1]],0) -> 0 | M5: =IFERROR(VLOOKUP(Tabla5[[#This Row],[Producto 2]],Tabla3[[Nombre]:[Ud]],5,FALSE)*Tabla5[[#This Row],[Cantidad 2]],0) -> 0 | P5: =IFERROR(VLOOKUP(Tabla5[[#This Row],[Producto 3]],Tabla3[[Nombre]:[Ud]],5,FALSE)*Tabla5[[#This Row],[Cantidad 3]],0) -> 0 | S5: =IFERROR(VLOOKUP(Tabla5[[#This Row],[Producto 4]],Tabla3[[Nombre]:[Ud]],5,FALSE)*Tabla5[[#This Row],[Cantidad 4]],0) -> 0 | V5: =IFERROR(VLOOKUP(Tabla5[[#This Row],[Producto 5]],Tabla3[[Nombre]:[Ud]],5,FALSE)*Tabla5[[#This Row],[Cantidad 5]],0) -> 0 | Y5: =IFERROR(VLOOKUP(Tabla5[[#This Row],[Producto 6]],Tabla3[[Nombre]:[Ud]],5,FALSE)*Tabla5[[#This Row],[Cantidad 6]],0) -> 0 | AB5: =IFERROR(VLOOKUP(Tabla5[[#This Row],[Producto 7]],Tabla3[[Nombre]:[Ud]],5,FALSE)*Tabla5[[#This Row],[Cantidad 7]],0) -> 0 | AE5: =IFERROR(VLOOKUP(Tabla5[[#This Row],[Producto 8]],Tabla3[[Nombre]:[Ud]],5,FALSE)*Tabla5[[#This Row],[Cantidad 8]],0) -> 0 | AH5: =IFERROR(VLOOKUP(Tabla5[[#This Row],[Producto 9]],Tabla3[[Nombre]:[Ud]],5,FALSE)*Tabla5[[#This Row],[Cantidad 9]],0) -> 0 | AK5: =IFERROR(VLOOKUP(Tabla5[[#This Row],[Producto 10]],Tabla3[[Nombre]:[Ud]],5,FALSE)*Tabla5[[#This Row],[Cantidad 10]],0) -> 0 | AN5: =IFERROR(VLOOKUP(Tabla5[[#This Row],[Producto 11]],Tabla3[[Nombre]:[Ud]],5,FALSE)*Tabla5[[#This Row],[Cantidad 11]],0) -> 0 | AQ5: =IFERROR(VLOOKUP(Tabla5[[#This Row],[Producto 12]],Tabla3[[Nombre]:[Ud]],5,FALSE)*Tabla5[[#This Row],[Cantidad 12]],0) -> 0 | AT5: =IFERROR(VLOOKUP(Tabla5[[#This Row],[Producto 13]],Tabla3[[Nombre]:[Ud]],5,FALSE)*Tabla5[[#This Row],[Cantidad 13]],0) -> 0 | AW5: =IFERROR(VLOOKUP(Tabla5[[#This Row],[Producto 14]],Tabla3[[Nombre]:[Ud]],5,FALSE)*Tabla5[[#This Row],[Cantidad 14]],0) -> 0 | AZ5: =IFERROR(VLOOKUP(Tabla5[[#This Row],[Producto 15]],Tabla3[[Nombre]:[Ud]],5,FALSE)*Tabla5[[#This Row],[Cantidad 15]],0) -> 0 | BC5: =IFERROR(VLOOKUP(Tabla5[[#This Row],[Producto 16]],Tabla3[[Nombre]:[Ud]],5,FALSE)*Tabla5[[#This Row],[Cantidad 16]],0) -> 0 | BF5: =IFERROR(VLOOKUP(Tabla5[[#This Row],[Producto 17]],Tabla3[[Nombre]:[Ud]],5,FALSE)*Tabla5[[#This Row],[Cantidad 17]],0) -> 0 | BI5: =IFERROR(VLOOKUP(Tabla5[[#This Row],[Producto 18]],Tabla3[[Nombre]:[Ud]],5,FALSE)*Tabla5[[#This Row],[Cantidad 18]],0) -> 0 | BL5: =IFERROR(VLOOKUP(Tabla5[[#This Row],[Producto 19]],Tabla3[[Nombre]:[Ud]],5,FALSE)*Tabla5[[#This Row],[Cantidad 19]],0) -> 0 | BO5: =IFERROR(VLOOKUP(Tabla5[[#This Row],[Producto 20]],Tabla3[[Nombre]:[Ud]],5,FALSE)*Tabla5[[#This Row],[Cantidad 20]],0) -> 0 | BR5: =IFERROR(VLOOKUP(Tabla5[[#This Row],[Producto 21]],Tabla3[[Nombre]:[Ud]],5,FALSE)*Tabla5[[#This Row],[Cantidad 21]],0) -> 0 | BU5: =IFERROR(VLOOKUP(Tabla5[[#This Row],[Producto 22]],Tabla3[[Nombre]:[Ud]],5,FALSE)*Tabla5[[#This Row],[Cantidad 22]],0) -> 0 | BX5: =IFERROR(VLOOKUP(Tabla5[[#This Row],[Producto 23]],Tabla3[[Nombre]:[Ud]],5,FALSE)*Tabla5[[#This Row],[Cantidad 23]],0) -> 0 | CA5: =IFERROR(VLOOKUP(Tabla5[[#This Row],[Producto 24]],Tabla3[[Nombre]:[Ud]],5,FALSE)*Tabla5[[#This Row],[Cantidad 24]],0) -> 0 | CD5: =IFERROR(VLOOKUP(Tabla5[[#This Row],[Producto 25]],Tabla3[[Nombre]:[Ud]],5,FALSE)*Tabla5[[#This Row],[Cantidad 25]],0) -> 0 | CG5: =IFERROR(VLOOKUP(Tabla5[[#This Row],[Producto 26]],Tabla3[[Nombre]:[Ud]],5,FALSE)*Tabla5[[#This Row],[Cantidad 26]],0) -> 0 | CJ5: =IFERROR(VLOOKUP(Tabla5[[#This Row],[Producto 27]],Tabla3[[Nombre]:[Ud]],5,FALSE)*Tabla5[[#This Row],[Cantidad 27]],0) -> 0 | CM5: =IFERROR(VLOOKUP(Tabla5[[#This Row],[Producto 28]],Tabla3[[Nombre]:[Ud]],5,FALSE)*Tabla5[[#This Row],[Cantidad 28]],0) -> 0 | CP5: =IFERROR(VLOOKUP(Tabla5[[#This Row],[Producto 29]],Tabla3[[Nombre]:[Ud]],5,FALSE)*Tabla5[[#This Row],[Cantidad 29]],0) -> 0 | CS5: =IFERROR(VLOOKUP(Tabla5[[#This Row],[Producto 30]],Tabla3[[Nombre]:[Ud]],5,FALSE)*Tabla5[[#This Row],[Cantidad 30]],0) -> 0
A6: 4 | D6: =Tabla5[[#This Row],[Gastos Generales]]+Tabla5[[#This Row],[Coste Persona]]+Tabla5[[#This Row],[Coste 1]]+Tabla5[[#This Row],[Coste 2]]+Tabla5[[#This Row],[Coste 3]]+Tabla5[[#This Row],[Coste 4]]+Tabla5[[#This Row],[Coste 5]]+Tabla5[[#This Row],[Coste 6]]+Tabla5[[#This Row],[Coste 7]]+Tabla5[[#This Row],[Coste 8]]+Tabla5[[#This Row],[Coste 9]]+Tabla5[[#This Row],[Coste 10]]+Tabla5[[#This Row],[Coste 11]]+Tabla5[[#This Row],[Coste 12]]+Tabla5[[#This Row],[Coste 13]]+Tabla5[[#This Row],[Coste 14]]+Tabla5[[#This Row],[Coste 15]]+Tabla5[[#This Row],[Coste 16]]+Tabla5[[#This Row],[Coste 17]]+Tabla5[[#This Row],[Coste 18]]+Tabla5[[#This Row],[Coste 19]]+Tabla5[[#This Row],[Coste 20]]+Tabla5[[#This Row],[Coste 21]]+Tabla5[[#This Row],[Coste 22]]+Tabla5[[#This Row],[Coste 23]]+Tabla5[[#This Row],[Coste 24]]+Tabla5[[#This Row],[Coste 25]]+Tabla5[[#This Row],[Coste 26]]+Tabla5[[#This Row],[Coste 27]]+Tabla5[[#This Row],[Coste 28]]+Tabla5[[#This Row],[Coste 29]]+Tabla5[[#This Row],[Coste 30]] -> 0 | E6: =Tabla5[[#This Row],[Minutos]]*Tabla13[[#Totals],[Precio Unitario]] -> 0 | G6: =IFERROR(VLOOKUP(Tabla5[[#This Row],[Persona]],Tabla1[[Nombre]:[Ud]],7,FALSE) *Tabla5[[#This Row],[Minutos]],0) -> 0 | J6: =IFERROR(VLOOKUP(Tabla5[[#This Row],[Producto 1]],Tabla3[[Nombre]:[Ud]],5,FALSE)*Tabla5[[#This Row],[Cantidad 1]],0) -> 0 | M6: =IFERROR(VLOOKUP(Tabla5[[#This Row],[Producto 2]],Tabla3[[Nombre]:[Ud]],5,FALSE)*Tabla5[[#This Row],[Cantidad 2]],0) -> 0 | P6: =IFERROR(VLOOKUP(Tabla5[[#This Row],[Producto 3]],Tabla3[[Nombre]:[Ud]],5,FALSE)*Tabla5[[#This Row],[Cantidad 3]],0) -> 0 | S6: =IFERROR(VLOOKUP(Tabla5[[#This Row],[Producto 4]],Tabla3[[Nombre]:[Ud]],5,FALSE)*Tabla5[[#This Row],[Cantidad 4]],0) -> 0 | V6: =IFERROR(VLOOKUP(Tabla5[[#This Row],[Producto 5]],Tabla3[[Nombre]:[Ud]],5,FALSE)*Tabla5[[#This Row],[Cantidad 5]],0) -> 0 | Y6: =IFERROR(VLOOKUP(Tabla5[[#This Row],[Producto 6]],Tabla3[[Nombre]:[Ud]],5,FALSE)*Tabla5[[#This Row],[Cantidad 6]],0) -> 0 | AB6: =IFERROR(VLOOKUP(Tabla5[[#This Row],[Producto 7]],Tabla3[[Nombre]:[Ud]],5,FALSE)*Tabla5[[#This Row],[Cantidad 7]],0) -> 0 | AE6: =IFERROR(VLOOKUP(Tabla5[[#This Row],[Producto 8]],Tabla3[[Nombre]:[Ud]],5,FALSE)*Tabla5[[#This Row],[Cantidad 8]],0) -> 0 | AH6: =IFERROR(VLOOKUP(Tabla5[[#This Row],[Producto 9]],Tabla3[[Nombre]:[Ud]],5,FALSE)*Tabla5[[#This Row],[Cantidad 9]],0) -> 0 | AK6: =IFERROR(VLOOKUP(Tabla5[[#This Row],[Producto 10]],Tabla3[[Nombre]:[Ud]],5,FALSE)*Tabla5[[#This Row],[Cantidad 10]],0) -> 0 | AN6: =IFERROR(VLOOKUP(Tabla5[[#This Row],[Producto 11]],Tabla3[[Nombre]:[Ud]],5,FALSE)*Tabla5[[#This Row],[Cantidad 11]],0) -> 0 | AQ6: =IFERROR(VLOOKUP(Tabla5[[#This Row],[Producto 12]],Tabla3[[Nombre]:[Ud]],5,FALSE)*Tabla5[[#This Row],[Cantidad 12]],0) -> 0 | AT6: =IFERROR(VLOOKUP(Tabla5[[#This Row],[Producto 13]],Tabla3[[Nombre]:[Ud]],5,FALSE)*Tabla5[[#This Row],[Cantidad 13]],0) -> 0 | AW6: =IFERROR(VLOOKUP(Tabla5[[#This Row],[Producto 14]],Tabla3[[Nombre]:[Ud]],5,FALSE)*Tabla5[[#This Row],[Cantidad 14]],0) -> 0 | AZ6: =IFERROR(VLOOKUP(Tabla5[[#This Row],[Producto 15]],Tabla3[[Nombre]:[Ud]],5,FALSE)*Tabla5[[#This Row],[Cantidad 15]],0) -> 0 | BC6: =IFERROR(VLOOKUP(Tabla5[[#This Row],[Producto 16]],Tabla3[[Nombre]:[Ud]],5,FALSE)*Tabla5[[#This Row],[Cantidad 16]],0) -> 0 | BF6: =IFERROR(VLOOKUP(Tabla5[[#This Row],[Producto 17]],Tabla3[[Nombre]:[Ud]],5,FALSE)*Tabla5[[#This Row],[Cantidad 17]],0) -> 0 | BI6: =IFERROR(VLOOKUP(Tabla5[[#This Row],[Producto 18]],Tabla3[[Nombre]:[Ud]],5,FALSE)*Tabla5[[#This Row],[Cantidad 18]],0) -> 0 | BL6: =IFERROR(VLOOKUP(Tabla5[[#This Row],[Producto 19]],Tabla3[[Nombre]:[Ud]],5,FALSE)*Tabla5[[#This Row],[Cantidad 19]],0) -> 0 | BO6: =IFERROR(VLOOKUP(Tabla5[[#This Row],[Producto 20]],Tabla3[[Nombre]:[Ud]],5,FALSE)*Tabla5[[#This Row],[Cantidad 20]],0) -> 0 | BR6: =IFERROR(VLOOKUP(Tabla5[[#This Row],[Producto 21]],Tabla3[[Nombre]:[Ud]],5,FALSE)*Tabla5[[#This Row],[Cantidad 21]],0) -> 0 | BU6: =IFERROR(VLOOKUP(Tabla5[[#This Row],[Producto 22]],Tabla3[[Nombre]:[Ud]],5,FALSE)*Tabla5[[#This Row],[Cantidad 22]],0) -> 0 | BX6: =IFERROR(VLOOKUP(Tabla5[[#This Row],[Producto 23]],Tabla3[[Nombre]:[Ud]],5,FALSE)*Tabla5[[#This Row],[Cantidad 23]],0) -> 0 | CA6: =IFERROR(VLOOKUP(Tabla5[[#This Row],[Producto 24]],Tabla3[[Nombre]:[Ud]],5,FALSE)*Tabla5[[#This Row],[Cantidad 24]],0) -> 0 | CD6: =IFERROR(VLOOKUP(Tabla5[[#This Row],[Producto 25]],Tabla3[[Nombre]:[Ud]],5,FALSE)*Tabla5[[#This Row],[Cantidad 25]],0) -> 0 | CG6: =IFERROR(VLOOKUP(Tabla5[[#This Row],[Producto 26]],Tabla3[[Nombre]:[Ud]],5,FALSE)*Tabla5[[#This Row],[Cantidad 26]],0) -> 0 | CJ6: =IFERROR(VLOOKUP(Tabla5[[#This Row],[Producto 27]],Tabla3[[Nombre]:[Ud]],5,FALSE)*Tabla5[[#This Row],[Cantidad 27]],0) -> 0 | CM6: =IFERROR(VLOOKUP(Tabla5[[#This Row],[Producto 28]],Tabla3[[Nombre]:[Ud]],5,FALSE)*Tabla5[[#This Row],[Cantidad 28]],0) -> 0 | CP6: =IFERROR(VLOOKUP(Tabla5[[#This Row],[Producto 29]],Tabla3[[Nombre]:[Ud]],5,FALSE)*Tabla5[[#This Row],[Cantidad 29]],0) -> 0 | CS6: =IFERROR(VLOOKUP(Tabla5[[#This Row],[Producto 30]],Tabla3[[Nombre]:[Ud]],5,FALSE)*Tabla5[[#This Row],[Cantidad 30]],0) -> 0
A7: 5 | D7: =Tabla5[[#This Row],[Gastos Generales]]+Tabla5[[#This Row],[Coste Persona]]+Tabla5[[#This Row],[Coste 1]]+Tabla5[[#This Row],[Coste 2]]+Tabla5[[#This Row],[Coste 3]]+Tabla5[[#This Row],[Coste 4]]+Tabla5[[#This Row],[Coste 5]]+Tabla5[[#This Row],[Coste 6]]+Tabla5[[#This Row],[Coste 7]]+Tabla5[[#This Row],[Coste 8]]+Tabla5[[#This Row],[Coste 9]]+Tabla5[[#This Row],[Coste 10]]+Tabla5[[#This Row],[Coste 11]]+Tabla5[[#This Row],[Coste 12]]+Tabla5[[#This Row],[Coste 13]]+Tabla5[[#This Row],[Coste 14]]+Tabla5[[#This Row],[Coste 15]]+Tabla5[[#This Row],[Coste 16]]+Tabla5[[#This Row],[Coste 17]]+Tabla5[[#This Row],[Coste 18]]+Tabla5[[#This Row],[Coste 19]]+Tabla5[[#This Row],[Coste 20]]+Tabla5[[#This Row],[Coste 21]]+Tabla5[[#This Row],[Coste 22]]+Tabla5[[#This Row],[Coste 23]]+Tabla5[[#This Row],[Coste 24]]+Tabla5[[#This Row],[Coste 25]]+Tabla5[[#This Row],[Coste 26]]+Tabla5[[#This Row],[Coste 27]]+Tabla5[[#This Row],[Coste 28]]+Tabla5[[#This Row],[Coste 29]]+Tabla5[[#This Row],[Coste 30]] -> 0 | E7: =Tabla5[[#This Row],[Minutos]]*Tabla13[[#Totals],[Precio Unitario]] -> 0 | G7: =IFERROR(VLOOKUP(Tabla5[[#This Row],[Persona]],Tabla1[[Nombre]:[Ud]],7,FALSE) *Tabla5[[#This Row],[Minutos]],0) -> 0 | J7: =IFERROR(VLOOKUP(Tabla5[[#This Row],[Producto 1]],Tabla3[[Nombre]:[Ud]],5,FALSE)*Tabla5[[#This Row],[Cantidad 1]],0) -> 0 | M7: =IFERROR(VLOOKUP(Tabla5[[#This Row],[Producto 2]],Tabla3[[Nombre]:[Ud]],5,FALSE)*Tabla5[[#This Row],[Cantidad 2]],0) -> 0 | P7: =IFERROR(VLOOKUP(Tabla5[[#This Row],[Producto 3]],Tabla3[[Nombre]:[Ud]],5,FALSE)*Tabla5[[#This Row],[Cantidad 3]],0) -> 0 | S7: =IFERROR(VLOOKUP(Tabla5[[#This Row],[Producto 4]],Tabla3[[Nombre]:[Ud]],5,FALSE)*Tabla5[[#This Row],[Cantidad 4]],0) -> 0 | V7: =IFERROR(VLOOKUP(Tabla5[[#This Row],[Producto 5]],Tabla3[[Nombre]:[Ud]],5,FALSE)*Tabla5[[#This Row],[Cantidad 5]],0) -> 0 | Y7: =IFERROR(VLOOKUP(Tabla5[[#This Row],[Producto 6]],Tabla3[[Nombre]:[Ud]],5,FALSE)*Tabla5[[#This Row],[Cantidad 6]],0) -> 0 | AB7: =IFERROR(VLOOKUP(Tabla5[[#This Row],[Producto 7]],Tabla3[[Nombre]:[Ud]],5,FALSE)*Tabla5[[#This Row],[Cantidad 7]],0) -> 0 | AE7: =IFERROR(VLOOKUP(Tabla5[[#This Row],[Producto 8]],Tabla3[[Nombre]:[Ud]],5,FALSE)*Tabla5[[#This Row],[Cantidad 8]],0) -> 0 | AH7: =IFERROR(VLOOKUP(Tabla5[[#This Row],[Producto 9]],Tabla3[[Nombre]:[Ud]],5,FALSE)*Tabla5[[#This Row],[Cantidad 9]],0) -> 0 | AK7: =IFERROR(VLOOKUP(Tabla5[[#This Row],[Producto 10]],Tabla3[[Nombre]:[Ud]],5,FALSE)*Tabla5[[#This Row],[Cantidad 10]],0) -> 0 | AN7: =IFERROR(VLOOKUP(Tabla5[[#This Row],[Producto 11]],Tabla3[[Nombre]:[Ud]],5,FALSE)*Tabla5[[#This Row],[Cantidad 11]],0) -> 0 | AQ7: =IFERROR(VLOOKUP(Tabla5[[#This Row],[Producto 12]],Tabla3[[Nombre]:[Ud]],5,FALSE)*Tabla5[[#This Row],[Cantidad 12]],0) -> 0 | AT7: =IFERROR(VLOOKUP(Tabla5[[#This Row],[Producto 13]],Tabla3[[Nombre]:[Ud]],5,FALSE)*Tabla5[[#This Row],[Cantidad 13]],0) -> 0 | AW7: =IFERROR(VLOOKUP(Tabla5[[#This Row],[Producto 14]],Tabla3[[Nombre]:[Ud]],5,FALSE)*Tabla5[[#This Row],[Cantidad 14]],0) -> 0 | AZ7: =IFERROR(VLOOKUP(Tabla5[[#This Row],[Producto 15]],Tabla3[[Nombre]:[Ud]],5,FALSE)*Tabla5[[#This Row],[Cantidad 15]],0) -> 0 | BC7: =IFERROR(VLOOKUP(Tabla5[[#This Row],[Producto 16]],Tabla3[[Nombre]:[Ud]],5,FALSE)*Tabla5[[#This Row],[Cantidad 16]],0) -> 0 | BF7: =IFERROR(VLOOKUP(Tabla5[[#This Row],[Producto 17]],Tabla3[[Nombre]:[Ud]],5,FALSE)*Tabla5[[#This Row],[Cantidad 17]],0) -> 0 | BI7: =IFERROR(VLOOKUP(Tabla5[[#This Row],[Producto 18]],Tabla3[[Nombre]:[Ud]],5,FALSE)*Tabla5[[#This Row],[Cantidad 18]],0) -> 0 | BL7: =IFERROR(VLOOKUP(Tabla5[[#This Row],[Producto 19]],Tabla3[[Nombre]:[Ud]],5,FALSE)*Tabla5[[#This Row],[Cantidad 19]],0) -> 0 | BO7: =IFERROR(VLOOKUP(Tabla5[[#This Row],[Producto 20]],Tabla3[[Nombre]:[Ud]],5,FALSE)*Tabla5[[#This Row],[Cantidad 20]],0) -> 0 | BR7: =IFERROR(VLOOKUP(Tabla5[[#This Row],[Producto 21]],Tabla3[[Nombre]:[Ud]],5,FALSE)*Tabla5[[#This Row],[Cantidad 21]],0) -> 0 | BU7: =IFERROR(VLOOKUP(Tabla5[[#This Row],[Producto 22]],Tabla3[[Nombre]:[Ud]],5,FALSE)*Tabla5[[#This Row],[Cantidad 22]],0) -> 0 | BX7: =IFERROR(VLOOKUP(Tabla5[[#This Row],[Producto 23]],Tabla3[[Nombre]:[Ud]],5,FALSE)*Tabla5[[#This Row],[Cantidad 23]],0) -> 0 | CA7: =IFERROR(VLOOKUP(Tabla5[[#This Row],[Producto 24]],Tabla3[[Nombre]:[Ud]],5,FALSE)*Tabla5[[#This Row],[Cantidad 24]],0) -> 0 | CD7: =IFERROR(VLOOKUP(Tabla5[[#This Row],[Producto 25]],Tabla3[[Nombre]:[Ud]],5,FALSE)*Tabla5[[#This Row],[Cantidad 25]],0) -> 0 | CG7: =IFERROR(VLOOKUP(Tabla5[[#This Row],[Producto 26]],Tabla3[[Nombre]:[Ud]],5,FALSE)*Tabla5[[#This Row],[Cantidad 26]],0) -> 0 | CJ7: =IFERROR(VLOOKUP(Tabla5[[#This Row],[Producto 27]],Tabla3[[Nombre]:[Ud]],5,FALSE)*Tabla5[[#This Row],[Cantidad 27]],0) -> 0 | CM7: =IFERROR(VLOOKUP(Tabla5[[#This Row],[Producto 28]],Tabla3[[Nombre]:[Ud]],5,FALSE)*Tabla5[[#This Row],[Cantidad 28]],0) -> 0 | CP7: =IFERROR(VLOOKUP(Tabla5[[#This Row],[Producto 29]],Tabla3[[Nombre]:[Ud]],5,FALSE)*Tabla5[[#This Row],[Cantidad 29]],0) -> 0 | CS7: =IFERROR(VLOOKUP(Tabla5[[#This Row],[Producto 30]],Tabla3[[Nombre]:[Ud]],5,FALSE)*Tabla5[[#This Row],[Cantidad 30]],0) -> 0
A8: 6 | D8: =Tabla5[[#This Row],[Gastos Generales]]+Tabla5[[#This Row],[Coste Persona]]+Tabla5[[#This Row],[Coste 1]]+Tabla5[[#This Row],[Coste 2]]+Tabla5[[#This Row],[Coste 3]]+Tabla5[[#This Row],[Coste 4]]+Tabla5[[#This Row],[Coste 5]]+Tabla5[[#This Row],[Coste 6]]+Tabla5[[#This Row],[Coste 7]]+Tabla5[[#This Row],[Coste 8]]+Tabla5[[#This Row],[Coste 9]]+Tabla5[[#This Row],[Coste 10]]+Tabla5[[#This Row],[Coste 11]]+Tabla5[[#This Row],[Coste 12]]+Tabla5[[#This Row],[Coste 13]]+Tabla5[[#This Row],[Coste 14]]+Tabla5[[#This Row],[Coste 15]]+Tabla5[[#This Row],[Coste 16]]+Tabla5[[#This Row],[Coste 17]]+Tabla5[[#This Row],[Coste 18]]+Tabla5[[#This Row],[Coste 19]]+Tabla5[[#This Row],[Coste 20]]+Tabla5[[#This Row],[Coste 21]]+Tabla5[[#This Row],[Coste 22]]+Tabla5[[#This Row],[Coste 23]]+Tabla5[[#This Row],[Coste 24]]+Tabla5[[#This Row],[Coste 25]]+Tabla5[[#This Row],[Coste 26]]+Tabla5[[#This Row],[Coste 27]]+Tabla5[[#This Row],[Coste 28]]+Tabla5[[#This Row],[Coste 29]]+Tabla5[[#This Row],[Coste 30]] -> 0 | E8: =Tabla5[[#This Row],[Minutos]]*Tabla13[[#Totals],[Precio Unitario]] -> 0 | G8: =IFERROR(VLOOKUP(Tabla5[[#This Row],[Persona]],Tabla1[[Nombre]:[Ud]],7,FALSE) *Tabla5[[#This Row],[Minutos]],0) -> 0 | J8: =IFERROR(VLOOKUP(Tabla5[[#This Row],[Producto 1]],Tabla3[[Nombre]:[Ud]],5,FALSE)*Tabla5[[#This Row],[Cantidad 1]],0) -> 0 | M8: =IFERROR(VLOOKUP(Tabla5[[#This Row],[Producto 2]],Tabla3[[Nombre]:[Ud]],5,FALSE)*Tabla5[[#This Row],[Cantidad 2]],0) -> 0 | P8: =IFERROR(VLOOKUP(Tabla5[[#This Row],[Producto 3]],Tabla3[[Nombre]:[Ud]],5,FALSE)*Tabla5[[#This Row],[Cantidad 3]],0) -> 0 | S8: =IFERROR(VLOOKUP(Tabla5[[#This Row],[Producto 4]],Tabla3[[Nombre]:[Ud]],5,FALSE)*Tabla5[[#This Row],[Cantidad 4]],0) -> 0 | V8: =IFERROR(VLOOKUP(Tabla5[[#This Row],[Producto 5]],Tabla3[[Nombre]:[Ud]],5,FALSE)*Tabla5[[#This Row],[Cantidad 5]],0) -> 0 | Y8: =IFERROR(VLOOKUP(Tabla5[[#This Row],[Producto 6]],Tabla3[[Nombre]:[Ud]],5,FALSE)*Tabla5[[#This Row],[Cantidad 6]],0) -> 0 | AB8: =IFERROR(VLOOKUP(Tabla5[[#This Row],[Producto 7]],Tabla3[[Nombre]:[Ud]],5,FALSE)*Tabla5[[#This Row],[Cantidad 7]],0) -> 0 | AE8: =IFERROR(VLOOKUP(Tabla5[[#This Row],[Producto 8]],Tabla3[[Nombre]:[Ud]],5,FALSE)*Tabla5[[#This Row],[Cantidad 8]],0) -> 0 | AH8: =IFERROR(VLOOKUP(Tabla5[[#This Row],[Producto 9]],Tabla3[[Nombre]:[Ud]],5,FALSE)*Tabla5[[#This Row],[Cantidad 9]],0) -> 0 | AK8: =IFERROR(VLOOKUP(Tabla5[[#This Row],[Producto 10]],Tabla3[[Nombre]:[Ud]],5,FALSE)*Tabla5[[#This Row],[Cantidad 10]],0) -> 0 | AN8: =IFERROR(VLOOKUP(Tabla5[[#This Row],[Producto 11]],Tabla3[[Nombre]:[Ud]],5,FALSE)*Tabla5[[#This Row],[Cantidad 11]],0) -> 0 | AQ8: =IFERROR(VLOOKUP(Tabla5[[#This Row],[Producto 12]],Tabla3[[Nombre]:[Ud]],5,FALSE)*Tabla5[[#This Row],[Cantidad 12]],0) -> 0 | AT8: =IFERROR(VLOOKUP(Tabla5[[#This Row],[Producto 13]],Tabla3[[Nombre]:[Ud]],5,FALSE)*Tabla5[[#This Row],[Cantidad 13]],0) -> 0 | AW8: =IFERROR(VLOOKUP(Tabla5[[#This Row],[Producto 14]],Tabla3[[Nombre]:[Ud]],5,FALSE)*Tabla5[[#This Row],[Cantidad 14]],0) -> 0 | AZ8: =IFERROR(VLOOKUP(Tabla5[[#This Row],[Producto 15]],Tabla3[[Nombre]:[Ud]],5,FALSE)*Tabla5[[#This Row],[Cantidad 15]],0) -> 0 | BC8: =IFERROR(VLOOKUP(Tabla5[[#This Row],[Producto 16]],Tabla3[[Nombre]:[Ud]],5,FALSE)*Tabla5[[#This Row],[Cantidad 16]],0) -> 0 | BF8: =IFERROR(VLOOKUP(Tabla5[[#This Row],[Producto 17]],Tabla3[[Nombre]:[Ud]],5,FALSE)*Tabla5[[#This Row],[Cantidad 17]],0) -> 0 | BI8: =IFERROR(VLOOKUP(Tabla5[[#This Row],[Producto 18]],Tabla3[[Nombre]:[Ud]],5,FALSE)*Tabla5[[#This Row],[Cantidad 18]],0) -> 0 | BL8: =IFERROR(VLOOKUP(Tabla5[[#This Row],[Producto 19]],Tabla3[[Nombre]:[Ud]],5,FALSE)*Tabla5[[#This Row],[Cantidad 19]],0) -> 0 | BO8: =IFERROR(VLOOKUP(Tabla5[[#This Row],[Producto 20]],Tabla3[[Nombre]:[Ud]],5,FALSE)*Tabla5[[#This Row],[Cantidad 20]],0) -> 0 | BR8: =IFERROR(VLOOKUP(Tabla5[[#This Row],[Producto 21]],Tabla3[[Nombre]:[Ud]],5,FALSE)*Tabla5[[#This Row],[Cantidad 21]],0) -> 0 | BU8: =IFERROR(VLOOKUP(Tabla5[[#This Row],[Producto 22]],Tabla3[[Nombre]:[Ud]],5,FALSE)*Tabla5[[#This Row],[Cantidad 22]],0) -> 0 | BX8: =IFERROR(VLOOKUP(Tabla5[[#This Row],[Producto 23]],Tabla3[[Nombre]:[Ud]],5,FALSE)*Tabla5[[#This Row],[Cantidad 23]],0) -> 0 | CA8: =IFERROR(VLOOKUP(Tabla5[[#This Row],[Producto 24]],Tabla3[[Nombre]:[Ud]],5,FALSE)*Tabla5[[#This Row],[Cantidad 24]],0) -> 0 | CD8: =IFERROR(VLOOKUP(Tabla5[[#This Row],[Producto 25]],Tabla3[[Nombre]:[Ud]],5,FALSE)*Tabla5[[#This Row],[Cantidad 25]],0) -> 0 | CG8: =IFERROR(VLOOKUP(Tabla5[[#This Row],[Producto 26]],Tabla3[[Nombre]:[Ud]],5,FALSE)*Tabla5[[#This Row],[Cantidad 26]],0) -> 0 | CJ8: =IFERROR(VLOOKUP(Tabla5[[#This Row],[Producto 27]],Tabla3[[Nombre]:[Ud]],5,FALSE)*Tabla5[[#This Row],[Cantidad 27]],0) -> 0 | CM8: =IFERROR(VLOOKUP(Tabla5[[#This Row],[Producto 28]],Tabla3[[Nombre]:[Ud]],5,FALSE)*Tabla5[[#This Row],[Cantidad 28]],0) -> 0 | CP8: =IFERROR(VLOOKUP(Tabla5[[#This Row],[Producto 29]],Tabla3[[Nombre]:[Ud]],5,FALSE)*Tabla5[[#This Row],[Cantidad 29]],0) -> 0 | CS8: =IFERROR(VLOOKUP(Tabla5[[#This Row],[Producto 30]],Tabla3[[Nombre]:[Ud]],5,FALSE)*Tabla5[[#This Row],[Cantidad 30]],0) -> 0
A9: 7 | D9: =Tabla5[[#This Row],[Gastos Generales]]+Tabla5[[#This Row],[Coste Persona]]+Tabla5[[#This Row],[Coste 1]]+Tabla5[[#This Row],[Coste 2]]+Tabla5[[#This Row],[Coste 3]]+Tabla5[[#This Row],[Coste 4]]+Tabla5[[#This Row],[Coste 5]]+Tabla5[[#This Row],[Coste 6]]+Tabla5[[#This Row],[Coste 7]]+Tabla5[[#This Row],[Coste 8]]+Tabla5[[#This Row],[Coste 9]]+Tabla5[[#This Row],[Coste 10]]+Tabla5[[#This Row],[Coste 11]]+Tabla5[[#This Row],[Coste 12]]+Tabla5[[#This Row],[Coste 13]]+Tabla5[[#This Row],[Coste 14]]+Tabla5[[#This Row],[Coste 15]]+Tabla5[[#This Row],[Coste 16]]+Tabla5[[#This Row],[Coste 17]]+Tabla5[[#This Row],[Coste 18]]+Tabla5[[#This Row],[Coste 19]]+Tabla5[[#This Row],[Coste 20]]+Tabla5[[#This Row],[Coste 21]]+Tabla5[[#This Row],[Coste 22]]+Tabla5[[#This Row],[Coste 23]]+Tabla5[[#This Row],[Coste 24]]+Tabla5[[#This Row],[Coste 25]]+Tabla5[[#This Row],[Coste 26]]+Tabla5[[#This Row],[Coste 27]]+Tabla5[[#This Row],[Coste 28]]+Tabla5[[#This Row],[Coste 29]]+Tabla5[[#This Row],[Coste 30]] -> 0 | E9: =Tabla5[[#This Row],[Minutos]]*Tabla13[[#Totals],[Precio Unitario]] -> 0 | G9: =IFERROR(VLOOKUP(Tabla5[[#This Row],[Persona]],Tabla1[[Nombre]:[Ud]],7,FALSE) *Tabla5[[#This Row],[Minutos]],0) -> 0 | J9: =IFERROR(VLOOKUP(Tabla5[[#This Row],[Producto 1]],Tabla3[[Nombre]:[Ud]],5,FALSE)*Tabla5[[#This Row],[Cantidad 1]],0) -> 0 | M9: =IFERROR(VLOOKUP(Tabla5[[#This Row],[Producto 2]],Tabla3[[Nombre]:[Ud]],5,FALSE)*Tabla5[[#This Row],[Cantidad 2]],0) -> 0 | P9: =IFERROR(VLOOKUP(Tabla5[[#This Row],[Producto 3]],Tabla3[[Nombre]:[Ud]],5,FALSE)*Tabla5[[#This Row],[Cantidad 3]],0) -> 0 | S9: =IFERROR(VLOOKUP(Tabla5[[#This Row],[Producto 4]],Tabla3[[Nombre]:[Ud]],5,FALSE)*Tabla5[[#This Row],[Cantidad 4]],0) -> 0 | V9: =IFERROR(VLOOKUP(Tabla5[[#This Row],[Producto 5]],Tabla3[[Nombre]:[Ud]],5,FALSE)*Tabla5[[#This Row],[Cantidad 5]],0) -> 0 | Y9: =IFERROR(VLOOKUP(Tabla5[[#This Row],[Producto 6]],Tabla3[[Nombre]:[Ud]],5,FALSE)*Tabla5[[#This Row],[Cantidad 6]],0) -> 0 | AB9: =IFERROR(VLOOKUP(Tabla5[[#This Row],[Producto 7]],Tabla3[[Nombre]:[Ud]],5,FALSE)*Tabla5[[#This Row],[Cantidad 7]],0) -> 0 | AE9: =IFERROR(VLOOKUP(Tabla5[[#This Row],[Producto 8]],Tabla3[[Nombre]:[Ud]],5,FALSE)*Tabla5[[#This Row],[Cantidad 8]],0) -> 0 | AH9: =IFERROR(VLOOKUP(Tabla5[[#This Row],[Producto 9]],Tabla3[[Nombre]:[Ud]],5,FALSE)*Tabla5[[#This Row],[Cantidad 9]],0) -> 0 | AK9: =IFERROR(VLOOKUP(Tabla5[[#This Row],[Producto 10]],Tabla3[[Nombre]:[Ud]],5,FALSE)*Tabla5[[#This Row],[Cantidad 10]],0) -> 0 | AN9: =IFERROR(VLOOKUP(Tabla5[[#This Row],[Producto 11]],Tabla3[[Nombre]:[Ud]],5,FALSE)*Tabla5[[#This Row],[Cantidad 11]],0) -> 0 | AQ9: =IFERROR(VLOOKUP(Tabla5[[#This Row],[Producto 12]],Tabla3[[Nombre]:[Ud]],5,FALSE)*Tabla5[[#This Row],[Cantidad 12]],0) -> 0 | AT9: =IFERROR(VLOOKUP(Tabla5[[#This Row],[Producto 13]],Tabla3[[Nombre]:[Ud]],5,FALSE)*Tabla5[[#This Row],[Cantidad 13]],0) -> 0 | AW9: =IFERROR(VLOOKUP(Tabla5[[#This Row],[Producto 14]],Tabla3[[Nombre]:[Ud]],5,FALSE)*Tabla5[[#This Row],[Cantidad 14]],0) -> 0 | AZ9: =IFERROR(VLOOKUP(Tabla5[[#This Row],[Producto 15]],Tabla3[[Nombre]:[Ud]],5,FALSE)*Tabla5[[#This Row],[Cantidad 15]],0) -> 0 | BC9: =IFERROR(VLOOKUP(Tabla5[[#This Row],[Producto 16]],Tabla3[[Nombre]:[Ud]],5,FALSE)*Tabla5[[#This Row],[Cantidad 16]],0) -> 0 | BF9: =IFERROR(VLOOKUP(Tabla5[[#This Row],[Producto 17]],Tabla3[[Nombre]:[Ud]],5,FALSE)*Tabla5[[#This Row],[Cantidad 17]],0) -> 0 | BI9: =IFERROR(VLOOKUP(Tabla5[[#This Row],[Producto 18]],Tabla3[[Nombre]:[Ud]],5,FALSE)*Tabla5[[#This Row],[Cantidad 18]],0) -> 0 | BL9: =IFERROR(VLOOKUP(Tabla5[[#This Row],[Producto 19]],Tabla3[[Nombre]:[Ud]],5,FALSE)*Tabla5[[#This Row],[Cantidad 19]],0) -> 0 | BO9: =IFERROR(VLOOKUP(Tabla5[[#This Row],[Producto 20]],Tabla3[[Nombre]:[Ud]],5,FALSE)*Tabla5[[#This Row],[Cantidad 20]],0) -> 0 | BR9: =IFERROR(VLOOKUP(Tabla5[[#This Row],[Producto 21]],Tabla3[[Nombre]:[Ud]],5,FALSE)*Tabla5[[#This Row],[Cantidad 21]],0) -> 0 | BU9: =IFERROR(VLOOKUP(Tabla5[[#This Row],[Producto 22]],Tabla3[[Nombre]:[Ud]],5,FALSE)*Tabla5[[#This Row],[Cantidad 22]],0) -> 0 | BX9: =IFERROR(VLOOKUP(Tabla5[[#This Row],[Producto 23]],Tabla3[[Nombre]:[Ud]],5,FALSE)*Tabla5[[#This Row],[Cantidad 23]],0) -> 0 | CA9: =IFERROR(VLOOKUP(Tabla5[[#This Row],[Producto 24]],Tabla3[[Nombre]:[Ud]],5,FALSE)*Tabla5[[#This Row],[Cantidad 24]],0) -> 0 | CD9: =IFERROR(VLOOKUP(Tabla5[[#This Row],[Producto 25]],Tabla3[[Nombre]:[Ud]],5,FALSE)*Tabla5[[#This Row],[Cantidad 25]],0) -> 0 | CG9: =IFERROR(VLOOKUP(Tabla5[[#This Row],[Producto 26]],Tabla3[[Nombre]:[Ud]],5,FALSE)*Tabla5[[#This Row],[Cantidad 26]],0) -> 0 | CJ9: =IFERROR(VLOOKUP(Tabla5[[#This Row],[Producto 27]],Tabla3[[Nombre]:[Ud]],5,FALSE)*Tabla5[[#This Row],[Cantidad 27]],0) -> 0 | CM9: =IFERROR(VLOOKUP(Tabla5[[#This Row],[Producto 28]],Tabla3[[Nombre]:[Ud]],5,FALSE)*Tabla5[[#This Row],[Cantidad 28]],0) -> 0 | CP9: =IFERROR(VLOOKUP(Tabla5[[#This Row],[Producto 29]],Tabla3[[Nombre]:[Ud]],5,FALSE)*Tabla5[[#This Row],[Cantidad 29]],0) -> 0 | CS9: =IFERROR(VLOOKUP(Tabla5[[#This Row],[Producto 30]],Tabla3[[Nombre]:[Ud]],5,FALSE)*Tabla5[[#This Row],[Cantidad 30]],0) -> 0
A10: 8 | D10: =Tabla5[[#This Row],[Gastos Generales]]+Tabla5[[#This Row],[Coste Persona]]+Tabla5[[#This Row],[Coste 1]]+Tabla5[[#This Row],[Coste 2]]+Tabla5[[#This Row],[Coste 3]]+Tabla5[[#This Row],[Coste 4]]+Tabla5[[#This Row],[Coste 5]]+Tabla5[[#This Row],[Coste 6]]+Tabla5[[#This Row],[Coste 7]]+Tabla5[[#This Row],[Coste 8]]+Tabla5[[#This Row],[Coste 9]]+Tabla5[[#This Row],[Coste 10]]+Tabla5[[#This Row],[Coste 11]]+Tabla5[[#This Row],[Coste 12]]+Tabla5[[#This Row],[Coste 13]]+Tabla5[[#This Row],[Coste 14]]+Tabla5[[#This Row],[Coste 15]]+Tabla5[[#This Row],[Coste 16]]+Tabla5[[#This Row],[Coste 17]]+Tabla5[[#This Row],[Coste 18]]+Tabla5[[#This Row],[Coste 19]]+Tabla5[[#This Row],[Coste 20]]+Tabla5[[#This Row],[Coste 21]]+Tabla5[[#This Row],[Coste 22]]+Tabla5[[#This Row],[Coste 23]]+Tabla5[[#This Row],[Coste 24]]+Tabla5[[#This Row],[Coste 25]]+Tabla5[[#This Row],[Coste 26]]+Tabla5[[#This Row],[Coste 27]]+Tabla5[[#This Row],[Coste 28]]+Tabla5[[#This Row],[Coste 29]]+Tabla5[[#This Row],[Coste 30]] -> 0 | E10: =Tabla5[[#This Row],[Minutos]]*Tabla13[[#Totals],[Precio Unitario]] -> 0 | G10: =IFERROR(VLOOKUP(Tabla5[[#This Row],[Persona]],Tabla1[[Nombre]:[Ud]],7,FALSE) *Tabla5[[#This Row],[Minutos]],0) -> 0 | J10: =IFERROR(VLOOKUP(Tabla5[[#This Row],[Producto 1]],Tabla3[[Nombre]:[Ud]],5,FALSE)*Tabla5[[#This Row],[Cantidad 1]],0) -> 0 | M10: =IFERROR(VLOOKUP(Tabla5[[#This Row],[Producto 2]],Tabla3[[Nombre]:[Ud]],5,FALSE)*Tabla5[[#This Row],[Cantidad 2]],0) -> 0 | P10: =IFERROR(VLOOKUP(Tabla5[[#This Row],[Producto 3]],Tabla3[[Nombre]:[Ud]],5,FALSE)*Tabla5[[#This Row],[Cantidad 3]],0) -> 0 | S10: =IFERROR(VLOOKUP(Tabla5[[#This Row],[Producto 4]],Tabla3[[Nombre]:[Ud]],5,FALSE)*Tabla5[[#This Row],[Cantidad 4]],0) -> 0 | V10: =IFERROR(VLOOKUP(Tabla5[[#This Row],[Producto 5]],Tabla3[[Nombre]:[Ud]],5,FALSE)*Tabla5[[#This Row],[Cantidad 5]],0) -> 0 | Y10: =IFERROR(VLOOKUP(Tabla5[[#This Row],[Producto 6]],Tabla3[[Nombre]:[Ud]],5,FALSE)*Tabla5[[#This Row],[Cantidad 6]],0) -> 0 | AB10: =IFERROR(VLOOKUP(Tabla5[[#This Row],[Producto 7]],Tabla3[[Nombre]:[Ud]],5,FALSE)*Tabla5[[#This Row],[Cantidad 7]],0) -> 0 | AE10: =IFERROR(VLOOKUP(Tabla5[[#This Row],[Producto 8]],Tabla3[[Nombre]:[Ud]],5,FALSE)*Tabla5[[#This Row],[Cantidad 8]],0) -> 0 | AH10: =IFERROR(VLOOKUP(Tabla5[[#This Row],[Producto 9]],Tabla3[[Nombre]:[Ud]],5,FALSE)*Tabla5[[#This Row],[Cantidad 9]],0) -> 0 | AK10: =IFERROR(VLOOKUP(Tabla5[[#This Row],[Producto 10]],Tabla3[[Nombre]:[Ud]],5,FALSE)*Tabla5[[#This Row],[Cantidad 10]],0) -> 0 | AN10: =IFERROR(VLOOKUP(Tabla5[[#This Row],[Producto 11]],Tabla3[[Nombre]:[Ud]],5,FALSE)*Tabla5[[#This Row],[Cantidad 11]],0) -> 0 | AQ10: =IFERROR(VLOOKUP(Tabla5[[#This Row],[Producto 12]],Tabla3[[Nombre]:[Ud]],5,FALSE)*Tabla5[[#This Row],[Cantidad 12]],0) -> 0 | AT10: =IFERROR(VLOOKUP(Tabla5[[#This Row],[Producto 13]],Tabla3[[Nombre]:[Ud]],5,FALSE)*Tabla5[[#This Row],[Cantidad 13]],0) -> 0 | AW10: =IFERROR(VLOOKUP(Tabla5[[#This Row],[Producto 14]],Tabla3[[Nombre]:[Ud]],5,FALSE)*Tabla5[[#This Row],[Cantidad 14]],0) -> 0 | AZ10: =IFERROR(VLOOKUP(Tabla5[[#This Row],[Producto 15]],Tabla3[[Nombre]:[Ud]],5,FALSE)*Tabla5[[#This Row],[Cantidad 15]],0) -> 0 | BC10: =IFERROR(VLOOKUP(Tabla5[[#This Row],[Producto 16]],Tabla3[[Nombre]:[Ud]],5,FALSE)*Tabla5[[#This Row],[Cantidad 16]],0) -> 0 | BF10: =IFERROR(VLOOKUP(Tabla5[[#This Row],[Producto 17]],Tabla3[[Nombre]:[Ud]],5,FALSE)*Tabla5[[#This Row],[Cantidad 17]],0) -> 0 | BI10: =IFERROR(VLOOKUP(Tabla5[[#This Row],[Producto 18]],Tabla3[[Nombre]:[Ud]],5,FALSE)*Tabla5[[#This Row],[Cantidad 18]],0) -> 0 | BL10: =IFERROR(VLOOKUP(Tabla5[[#This Row],[Producto 19]],Tabla3[[Nombre]:[Ud]],5,FALSE)*Tabla5[[#This Row],[Cantidad 19]],0) -> 0 | BO10: =IFERROR(VLOOKUP(Tabla5[[#This Row],[Producto 20]],Tabla3[[Nombre]:[Ud]],5,FALSE)*Tabla5[[#This Row],[Cantidad 20]],0) -> 0 | BR10: =IFERROR(VLOOKUP(Tabla5[[#This Row],[Producto 21]],Tabla3[[Nombre]:[Ud]],5,FALSE)*Tabla5[[#This Row],[Cantidad 21]],0) -> 0 | BU10: =IFERROR(VLOOKUP(Tabla5[[#This Row],[Producto 22]],Tabla3[[Nombre]:[Ud]],5,FALSE)*Tabla5[[#This Row],[Cantidad 22]],0) -> 0 | BX10: =IFERROR(VLOOKUP(Tabla5[[#This Row],[Producto 23]],Tabla3[[Nombre]:[Ud]],5,FALSE)*Tabla5[[#This Row],[Cantidad 23]],0) -> 0 | CA10: =IFERROR(VLOOKUP(Tabla5[[#This Row],[Producto 24]],Tabla3[[Nombre]:[Ud]],5,FALSE)*Tabla5[[#This Row],[Cantidad 24]],0) -> 0 | CD10: =IFERROR(VLOOKUP(Tabla5[[#This Row],[Producto 25]],Tabla3[[Nombre]:[Ud]],5,FALSE)*Tabla5[[#This Row],[Cantidad 25]],0) -> 0 | CG10: =IFERROR(VLOOKUP(Tabla5[[#This Row],[Producto 26]],Tabla3[[Nombre]:[Ud]],5,FALSE)*Tabla5[[#This Row],[Cantidad 26]],0) -> 0 | CJ10: =IFERROR(VLOOKUP(Tabla5[[#This Row],[Producto 27]],Tabla3[[Nombre]:[Ud]],5,FALSE)*Tabla5[[#This Row],[Cantidad 27]],0) -> 0 | CM10: =IFERROR(VLOOKUP(Tabla5[[#This Row],[Producto 28]],Tabla3[[Nombre]:[Ud]],5,FALSE)*Tabla5[[#This Row],[Cantidad 28]],0) -> 0 | CP10: =IFERROR(VLOOKUP(Tabla5[[#This Row],[Producto 29]],Tabla3[[Nombre]:[Ud]],5,FALSE)*Tabla5[[#This Row],[Cantidad 29]],0) -> 0 | CS10: =IFERROR(VLOOKUP(Tabla5[[#This Row],[Producto 30]],Tabla3[[Nombre]:[Ud]],5,FALSE)*Tabla5[[#This Row],[Cantidad 30]],0) -> 0
